Workbook

Sheet Dashboard
A1: TABLEAU DE BORD AER — PARC SOLAIRE & RESSOURCES HUMAINES
A3: Généré le 28/09/2026 — Sources : « Données sites / Répartition par antenne » (parc solaire, 499 sites) et « Données - Équipes » (personnel terrain).
A6: SITES INSTALLÉS | D6: PUISSANCE TOTALE (kWc) | G6: ANTENNES RÉSEAU SOLAIRE | J6: EFFECTIF RECOMMANDÉ (total) | M6: SITES / AGENT (moy.)
A7: =SUM('Antennes — Détail solaire'!E5:E13) -> 499 | D7: =SUM('Antennes — Détail solaire'!F5:F13) -> 32821.6 | G7: 9 | J7: =SUM('Antennes — Détail solaire'!J5:J13) -> 63 | M7: =SUM('Antennes — Détail solaire'!E5:E13)/SUM('Antennes — Détail solaire'!J5:J13) -> 7.9206349
A10: ÉQUIPES CONSTITUÉES | C10: POSTES POURVUS / REQUIS | F10: TOTAL MANQUES | H10: PERSONNEL DISPONIBLE (non affecté) | J10: MANQUE INGÉNIEURS | L10: MANQUE TECH. / CHAUFF.
A11: =COUNTIFS('Données - Équipes'!$C$5:$C$87,"Ingénieur") -> 16 | C11: =COUNTIF('Données - Équipes'!$F$5:$F$87,"OK")&" / "&(COUNTIF('Données - Équipes'!$F$5:$F$87,"OK")+COUNTIF('Données - Équipes'!$F$5:$F$87,"MANQUE")) -> 47 / 64 | F11: =COUNTIF('Données - Équipes'!$F$5:$F$87,"MANQUE") -> 17 | H11: =COUNTA('Données - Équipes'!$A$91:$A$104) -> 14 | J11: =COUNTIFS('Données - Équipes'!$C$5:$C$87,"Ingénieur",'Données - Équipes'!$F$5:$F$87,"MANQUE")&" / 16" -> 10 / 16 | L11: =COUNTIFS('Données - Équipes'!$C$5:$C$87,"Technicien 1",'Données - Équipes'!$F$5:$F$87,"MANQUE")+COUNTIFS('Données - Équipes'!$C$5:$C$87,"Technicien 2",'Données - Équipes'!$F$5:$F$87,"MANQUE")&" / 32 — "&COUNTIFS('Données - Équipes'!$C$5:$C$87,"Chauffeur",'Données - Équipes'!$F$5:$F$87,"MANQUE")&" / 16" -> 3 / 32 — 4 / 16
A12: PARC SOLAIRE — CHARGE ET DIMENSIONNEMENT PAR ANTENNE
A14: Antenne | B14: Type | C14: Régions / départements couverts | D14: Nb sites | E14: Puissance (kWc) | F14: Effectif recommandé | G14: % des sites | H14: Sites / agent
A15: Antenne Bamenda | B15: Principale | C15: Nord-Ouest, Ouest | D15: ='Antennes — Détail solaire'!E5 -> 79 | E15: ='Antennes — Détail solaire'!F5 -> 5234.6 | F15: ='Antennes — Détail solaire'!J5 -> 9 | G15: =D15/$D$24 -> 0.15831663 | H15: =IFERROR(D15/F15,0) -> 8.7777778
A16: Antenne Limbé | B16: Principale | C16: Littoral (hors Moungo), Sud-Ouest (hors Kupé) | D16: ='Antennes — Détail solaire'!E6 -> 50 | E16: ='Antennes — Détail solaire'!F6 -> 2677.6 | F16: ='Antennes — Détail solaire'!J6 -> 6 | G16: =D16/$D$24 -> 0.1002004 | H16: =IFERROR(D16/F16,0) -> 8.3333333
A17: Antenne Nkongsamba | B17: Annexe | C17: Moungo, Kupé-Manenguba, Nyong-et-Kellé | D17: ='Antennes — Détail solaire'!E7 -> 29 | E17: ='Antennes — Détail solaire'!F7 -> 1433.6 | F17: ='Antennes — Détail solaire'!J7 -> 5 | G17: =D17/$D$24 -> 0.058116232 | H17: =IFERROR(D17/F17,0) -> 5.8
A18: Antenne Garoua | B18: Principale | C18: Nord | D18: ='Antennes — Détail solaire'!E8 -> 46 | E18: ='Antennes — Détail solaire'!F8 -> 4341 | F18: ='Antennes — Détail solaire'!J8 -> 6 | G18: =D18/$D$24 -> 0.092184369 | H18: =IFERROR(D18/F18,0) -> 7.6666667
A19: Antenne Maroua | B19: Annexe | C19: Extrême-Nord | D19: ='Antennes — Détail solaire'!E9 -> 34 | E19: ='Antennes — Détail solaire'!F9 -> 3110.4 | F19: ='Antennes — Détail solaire'!J9 -> 6 | G19: =D19/$D$24 -> 0.068136273 | H19: =IFERROR(D19/F19,0) -> 5.6666667
A20: Antenne Ngaoundéré | B20: Annexe | C20: Adamaoua | D20: ='Antennes — Détail solaire'!E10 -> 55 | E20: ='Antennes — Détail solaire'!F10 -> 4312.8 | F20: ='Antennes — Détail solaire'!J10 -> 7 | G20: =D20/$D$24 -> 0.11022044 | H20: =IFERROR(D20/F20,0) -> 7.8571429
A21: Siège Yaoundé | B21: Principale | C21: Centre (reste) | D21: ='Antennes — Détail solaire'!E11 -> 71 | E21: ='Antennes — Détail solaire'!F11 -> 4015.2 | F21: ='Antennes — Détail solaire'!J11 -> 8 | G21: =D21/$D$24 -> 0.14228457 | H21: =IFERROR(D21/F21,0) -> 8.875
A22: Antenne Bertoua | B22: Annexe | C22: Est, Nyong-et-Mfoumou, Haute-Sanaga | D22: ='Antennes — Détail solaire'!E12 -> 68 | E22: ='Antennes — Détail solaire'!F12 -> 4498.2 | F22: ='Antennes — Détail solaire'!J12 -> 8 | G22: =D22/$D$24 -> 0.13627255 | H22: =IFERROR(D22/F22,0) -> 8.5
A23: Antenne Ebolowa | B23: Annexe | C23: Sud, Nyong-et-So'o | D23: ='Antennes — Détail solaire'!E13 -> 67 | E23: ='Antennes — Détail solaire'!F13 -> 3198.2 | F23: ='Antennes — Détail solaire'!J13 -> 8 | G23: =D23/$D$24 -> 0.13426854 | H23: =IFERROR(D23/F23,0) -> 8.375
A24: TOTAL (9 antennes) | D24: =SUM(D15:D23) -> 499 | E24: =SUM(E15:E23) -> 32821.6 | F24: =SUM(F15:F23) -> 63 | G24: =SUM(G15:G23) -> 1
A26: RESSOURCES HUMAINES — MANQUES PAR ANTENNE (déploiement terrain actuel)
A28: Antenne (nomenclature RH) | B28: Région (hypothèse) | C28: Ingénieur manquant | D28: Technicien manquant | E28: Chauffeur manquant | F28: Total manques | G28: Postes pourvus
A29: Extreme-Nord | B29: Extrême-Nord | C29: =COUNTIFS('Données - Équipes'!$G$5:$G$87,"Antenne Extreme-Nord",'Données - Équipes'!$C$5:$C$87,"Ingénieur",'Données - Équipes'!$F$5:$F$87,"MANQUE") -> 1 | D29: =COUNTIFS('Données - Équipes'!$G$5:$G$87,"Antenne Extreme-Nord",'Données - Équipes'!$C$5:$C$87,"Technicien 1",'Données - Équipes'!$F$5:$F$87,"MANQUE")+COUNTIFS('Données - Équipes'!$G$5:$G$87,"Antenne Extreme-Nord",'Données - Équipes'!$C$5:$C$87,"Technicien 2",'Données - Équipes'!$F$5:$F$87,"MANQUE") -> 0 | E29: =COUNTIFS('Données - Équipes'!$G$5:$G$87,"Antenne Extreme-Nord",'Données - Équipes'!$C$5:$C$87,"Chauffeur",'Données - Équipes'!$F$5:$F$87,"MANQUE") -> 0 | F29: =SUM(C29:E29) -> 1 | G29: =COUNTIFS('Données - Équipes'!$G$5:$G$87,"Antenne Extreme-Nord",'Données - Équipes'!$F$5:$F$87,"OK")&"/"&(COUNTIFS('Données - Équipes'!$G$5:$G$87,"Antenne Extreme-Nord",'Données - Équipes'!$F$5:$F$87,"OK")+COUNTIFS('Données - Équipes'!$G$5:$G$87,"Antenne Extreme-Nord",'Données - Équipes'!$F$5:$F$87,"MANQUE")) -> 3/4
A30: Nord | B30: Nord | C30: =COUNTIFS('Données - Équipes'!$G$5:$G$87,"Antenne Nord",'Données - Équipes'!$C$5:$C$87,"Ingénieur",'Données - Équipes'!$F$5:$F$87,"MANQUE") -> 1 | D30: =COUNTIFS('Données - Équipes'!$G$5:$G$87,"Antenne Nord",'Données - Équipes'!$C$5:$C$87,"Technicien 1",'Données - Équipes'!$F$5:$F$87,"MANQUE")+COUNTIFS('Données - Équipes'!$G$5:$G$87,"Antenne Nord",'Données - Équipes'!$C$5:$C$87,"Technicien 2",'Données - Équipes'!$F$5:$F$87,"MANQUE") -> 1 | E30: =COUNTIFS('Données - Équipes'!$G$5:$G$87,"Antenne Nord",'Données - Équipes'!$C$5:$C$87,"Chauffeur",'Données - Équipes'!$F$5:$F$87,"MANQUE") -> 1 | F30: =SUM(C30:E30) -> 3 | G30: =COUNTIFS('Données - Équipes'!$G$5:$G$87,"Antenne Nord",'Données - Équipes'!$F$5:$F$87,"OK")&"/"&(COUNTIFS('Données - Équipes'!$G$5:$G$87,"Antenne Nord",'Données - Équipes'!$F$5:$F$87,"OK")+COUNTIFS('Données - Équipes'!$G$5:$G$87,"Antenne Nord",'Données - Équipes'!$F$5:$F$87,"MANQUE")) -> 5/8
A31: Nord-Ouest | B31: Nord-Ouest | C31: =COUNTIFS('Données - Équipes'!$G$5:$G$87,"Antenne Nord-Ouest",'Données - Équipes'!$C$5:$C$87,"Ingénieur",'Données - Équipes'!$F$5:$F$87,"MANQUE") -> 2 | D31: =COUNTIFS('Données - Équipes'!$G$5:$G$87,"Antenne Nord-Ouest",'Données - Équipes'!$C$5:$C$87,"Technicien 1",'Données - Équipes'!$F$5:$F$87,"MANQUE")+COUNTIFS('Données - Équipes'!$G$5:$G$87,"Antenne Nord-Ouest",'Données - Équipes'!$C$5:$C$87,"Technicien 2",'Données - Équipes'!$F$5:$F$87,"MANQUE") -> 0 | E31: =COUNTIFS('Données - Équipes'!$G$5:$G$87,"Antenne Nord-Ouest",'Données - Équipes'!$C$5:$C$87,"Chauffeur",'Données - Équipes'!$F$5:$F$87,"MANQUE") -> 2 | F31: =SUM(C31:E31) -> 4 | G31: =COUNTIFS('Données - Équipes'!$G$5:$G$87,"Antenne Nord-Ouest",'Données - Équipes'!$F$5:$F$87,"OK")&"/"&(COUNTIFS('Données - Équipes'!$G$5:$G$87,"Antenne Nord-Ouest",'Données - Équipes'!$F$5:$F$87,"OK")+COUNTIFS('Données - Équipes'!$G$5:$G$87,"Antenne Nord-Ouest",'Données - Équipes'!$F$5:$F$87,"MANQUE")) -> 8/12
A32: Adamaoua | B32: Adamaoua | C32: =COUNTIFS('Données - Équipes'!$G$5:$G$87,"Antenne Adamaoua",'Données - Équipes'!$C$5:$C$87,"Ingénieur",'Données - Équipes'!$F$5:$F$87,"MANQUE") -> 0 | D32: =COUNTIFS('Données - Équipes'!$G$5:$G$87,"Antenne Adamaoua",'Données - Équipes'!$C$5:$C$87,"Technicien 1",'Données - Équipes'!$F$5:$F$87,"MANQUE")+COUNTIFS('Données - Équipes'!$G$5:$G$87,"Antenne Adamaoua",'Données - Équipes'!$C$5:$C$87,"Technicien 2",'Données - Équipes'!$F$5:$F$87,"MANQUE") -> 1 | E32: =COUNTIFS('Données - Équipes'!$G$5:$G$87,"Antenne Adamaoua",'Données - Équipes'!$C$5:$C$87,"Chauffeur",'Données - Équipes'!$F$5:$F$87,"MANQUE") -> 0 | F32: =SUM(C32:E32) -> 1 | G32: =COUNTIFS('Données - Équipes'!$G$5:$G$87,"Antenne Adamaoua",'Données - Équipes'!$F$5:$F$87,"OK")&"/"&(COUNTIFS('Données - Équipes'!$G$5:$G$87,"Antenne Adamaoua",'Données - Équipes'!$F$5:$F$87,"OK")+COUNTIFS('Données - Équipes'!$G$5:$G$87,"Antenne Adamaoua",'Données - Équipes'!$F$5:$F$87,"MANQUE")) -> 3/4
A33: Est | B33: Est | C33: =COUNTIFS('Données - Équipes'!$G$5:$G$87,"Antenne Est",'Données - Équipes'!$C$5:$C$87,"Ingénieur",'Données - Équipes'!$F$5:$F$87,"MANQUE") -> 2 | D33: =COUNTIFS('Données - Équipes'!$G$5:$G$87,"Antenne Est",'Données - Équipes'!$C$5:$C$87,"Technicien 1",'Données - Équipes'!$F$5:$F$87,"MANQUE")+COUNTIFS('Données - Équipes'!$G$5:$G$87,"Antenne Est",'Données - Équipes'!$C$5:$C$87,"Technicien 2",'Données - Équipes'!$F$5:$F$87,"MANQUE") -> 0 | E33: =COUNTIFS('Données - Équipes'!$G$5:$G$87,"Antenne Est",'Données - Équipes'!$C$5:$C$87,"Chauffeur",'Données - Équipes'!$F$5:$F$87,"MANQUE") -> 0 | F33: =SUM(C33:E33) -> 2 | G33: =COUNTIFS('Données - Équipes'!$G$5:$G$87,"Antenne Est",'Données - Équipes'!$F$5:$F$87,"OK")&"/"&(COUNTIFS('Données - Équipes'!$G$5:$G$87,"Antenne Est",'Données - Équipes'!$F$5:$F$87,"OK")+COUNTIFS('Données - Équipes'!$G$5:$G$87,"Antenne Est",'Données - Équipes'!$F$5:$F$87,"MANQUE")) -> 6/8
A34: Sud - Centre | B34: Sud & Centre* | C34: =COUNTIFS('Données - Équipes'!$G$5:$G$87,"Antenne Sud - Centre",'Données - Équipes'!$C$5:$C$87,"Ingénieur",'Données - Équipes'!$F$5:$F$87,"MANQUE") -> 1 | D34: =COUNTIFS('Données - Équipes'!$G$5:$G$87,"Antenne Sud - Centre",'Données - Équipes'!$C$5:$C$87,"Technicien 1",'Données - Équipes'!$F$5:$F$87,"MANQUE")+COUNTIFS('Données - Équipes'!$G$5:$G$87,"Antenne Sud - Centre",'Données - Équipes'!$C$5:$C$87,"Technicien 2",'Données - Équipes'!$F$5:$F$87,"MANQUE") -> 0 | E34: =COUNTIFS('Données - Équipes'!$G$5:$G$87,"Antenne Sud - Centre",'Données - Équipes'!$C$5:$C$87,"Chauffeur",'Données - Équipes'!$F$5:$F$87,"MANQUE") -> 1 | F34: =SUM(C34:E34) -> 2 | G34: =COUNTIFS('Données - Équipes'!$G$5:$G$87,"Antenne Sud - Centre",'Données - Équipes'!$F$5:$F$87,"OK")&"/"&(COUNTIFS('Données - Équipes'!$G$5:$G$87,"Antenne Sud - Centre",'Données - Équipes'!$F$5:$F$87,"OK")+COUNTIFS('Données - Équipes'!$G$5:$G$87,"Antenne Sud - Centre",'Données - Équipes'!$F$5:$F$87,"MANQUE")) -> 6/8
A35: Sud-Ouest | B35: Sud-Ouest | C35: =COUNTIFS('Données - Équipes'!$G$5:$G$87,"Antenne Sud-Ouest",'Données - Équipes'!$C$5:$C$87,"Ingénieur",'Données - Équipes'!$F$5:$F$87,"MANQUE") -> 1 | D35: =COUNTIFS('Données - Équipes'!$G$5:$G$87,"Antenne Sud-Ouest",'Données - Équipes'!$C$5:$C$87,"Technicien 1",'Données - Équipes'!$F$5:$F$87,"MANQUE")+COUNTIFS('Données - Équipes'!$G$5:$G$87,"Antenne Sud-Ouest",'Données - Équipes'!$C$5:$C$87,"Technicien 2",'Données - Équipes'!$F$5:$F$87,"MANQUE") -> 0 | E35: =COUNTIFS('Données - Équipes'!$G$5:$G$87,"Antenne Sud-Ouest",'Données - Équipes'!$C$5:$C$87,"Chauffeur",'Données - Équipes'!$F$5:$F$87,"MANQUE") -> 0 | F35: =SUM(C35:E35) -> 1 | G35: =COUNTIFS('Données - Équipes'!$G$5:$G$87,"Antenne Sud-Ouest",'Données - Équipes'!$F$5:$F$87,"OK")&"/"&(COUNTIFS('Données - Équipes'!$G$5:$G$87,"Antenne Sud-Ouest",'Données - Équipes'!$F$5:$F$87,"OK")+COUNTIFS('Données - Équipes'!$G$5:$G$87,"Antenne Sud-Ouest",'Données - Équipes'!$F$5:$F$87,"MANQUE")) -> 3/4
A36: Sud-Ouest NKONSAMBA | B36: Littoral* | C36: =COUNTIFS('Données - Équipes'!$G$5:$G$87,"Annexe Sud-Ouest NKONSAMBA",'Données - Équipes'!$C$5:$C$87,"Ingénieur",'Données - Équipes'!$F$5:$F$87,"MANQUE") -> 2 | D36: =COUNTIFS('Données - Équipes'!$G$5:$G$87,"Annexe Sud-Ouest NKONSAMBA",'Données - Équipes'!$C$5:$C$87,"Technicien 1",'Données - Équipes'!$F$5:$F$87,"MANQUE")+COUNTIFS('Données - Équipes'!$G$5:$G$87,"Annexe Sud-Ouest NKONSAMBA",'Données - Équipes'!$C$5:$C$87,"Technicien 2",'Données - Équipes'!$F$5:$F$87,"MANQUE") -> 0 | E36: =COUNTIFS('Données - Équipes'!$G$5:$G$87,"Annexe Sud-Ouest NKONSAMBA",'Données - Équipes'!$C$5:$C$87,"Chauffeur",'Données - Équipes'!$F$5:$F$87,"MANQUE") -> 0 | F36: =SUM(C36:E36) -> 2 | G36: =COUNTIFS('Données - Équipes'!$G$5:$G$87,"Annexe Sud-Ouest NKONSAMBA",'Données - Équipes'!$F$5:$F$87,"OK")&"/"&(COUNTIFS('Données - Équipes'!$G$5:$G$87,"Annexe Sud-Ouest NKONSAMBA",'Données - Équipes'!$F$5:$F$87,"OK")+COUNTIFS('Données - Équipes'!$G$5:$G$87,"Annexe Sud-Ouest NKONSAMBA",'Données - Équipes'!$F$5:$F$87,"MANQUE")) -> 6/8
A37: Siège Yaoundé | B37: Centre (Siège) | C37: =COUNTIFS('Données - Équipes'!$G$5:$G$87,"Siege Yaoundé",'Données - Équipes'!$C$5:$C$87,"Ingénieur",'Données - Équipes'!$F$5:$F$87,"MANQUE") -> 0 | D37: =COUNTIFS('Données - Équipes'!$G$5:$G$87,"Siege Yaoundé",'Données - Équipes'!$C$5:$C$87,"Technicien 1",'Données - Équipes'!$F$5:$F$87,"MANQUE")+COUNTIFS('Données - Équipes'!$G$5:$G$87,"Siege Yaoundé",'Données - Équipes'!$C$5:$C$87,"Technicien 2",'Données - Équipes'!$F$5:$F$87,"MANQUE") -> 1 | E37: =COUNTIFS('Données - Équipes'!$G$5:$G$87,"Siege Yaoundé",'Données - Équipes'!$C$5:$C$87,"Chauffeur",'Données - Équipes'!$F$5:$F$87,"MANQUE") -> 0 | F37: =SUM(C37:E37) -> 1 | G37: =COUNTIFS('Données - Équipes'!$G$5:$G$87,"Siege Yaoundé",'Données - Équipes'!$F$5:$F$87,"OK")&"/"&(COUNTIFS('Données - Équipes'!$G$5:$G$87,"Siege Yaoundé",'Données - Équipes'!$F$5:$F$87,"OK")+COUNTIFS('Données - Équipes'!$G$5:$G$87,"Siege Yaoundé",'Données - Équipes'!$F$5:$F$87,"MANQUE")) -> 7/8
A38: TOTAL (9 antennes / 16 équipes) | C38: =SUM(C29:C37) -> 10 | D38: =SUM(D29:D37) -> 3 | E38: =SUM(E29:E37) -> 4 | F38: =SUM(F29:F37) -> 17
A40: MANQUES PAR PROFIL | H40: STATUT DES 16 ÉQUIPES (OK / manquant)
A42: Profil | B42: Besoin (16 équipes) | C42: Présent | D42: Manque | E42: Disponible (non affecté) | H42: Équipe (antenne — zone) | I42: Ingénieur | J42: Technicien 1 | K42: Technicien 2 | L42: Chauffeur | M42: Statut équipe
A43: Ingénieur | B43: 16 | C43: =COUNTIFS('Données - Équipes'!$C$5:$C$87,"Ingénieur",'Données - Équipes'!$F$5:$F$87,"OK") -> 6 | D43: =COUNTIFS('Données - Équipes'!$C$5:$C$87,"Ingénieur",'Données - Équipes'!$F$5:$F$87,"MANQUE") -> 10 | E43: =COUNTIF('Données - Équipes'!$C$91:$C$104,"Ingénieur") -> 3 | H43: Extrême-Nord — Z1 | I43: =IF(COUNTIFS('Données - Équipes'!$G$5:$G$87,"Antenne Extreme-Nord",'Données - Équipes'!$I$5:$I$87,1,'Données - Équipes'!$C$5:$C$87,"Ingénieur",'Données - Équipes'!$F$5:$F$87,"OK")>0,"OK","—") -> — | J43: =IF(COUNTIFS('Données - Équipes'!$G$5:$G$87,"Antenne Extreme-Nord",'Données - Équipes'!$I$5:$I$87,1,'Données - Équipes'!$C$5:$C$87,"Technicien 1",'Données - Équipes'!$F$5:$F$87,"OK")>0,"OK","—") -> OK | K43: =IF(COUNTIFS('Données - Équipes'!$G$5:$G$87,"Antenne Extreme-Nord",'Données - Équipes'!$I$5:$I$87,1,'Données - Équipes'!$C$5:$C$87,"Technicien 2",'Données - Équipes'!$F$5:$F$87,"OK")>0,"OK","—") -> OK | L43: =IF(COUNTIFS('Données - Équipes'!$G$5:$G$87,"Antenne Extreme-Nord",'Données - Équipes'!$I$5:$I$87,1,'Données - Équipes'!$C$5:$C$87,"Chauffeur",'Données - Équipes'!$F$5:$F$87,"OK")>0,"OK","—") -> OK | M43: =IF(COUNTIF(I43:L43,"OK")=4,"Complète",IF(COUNTIF(I43:L43,"OK")=0,"Critique","Partielle")) -> Partielle
A44: Technicien | B44: 32 | C44: =COUNTIFS('Données - Équipes'!$C$5:$C$87,"Technicien 1",'Données - Équipes'!$F$5:$F$87,"OK")+COUNTIFS('Données - Équipes'!$C$5:$C$87,"Technicien 2",'Données - Équipes'!$F$5:$F$87,"OK") -> 29 | D44: =COUNTIFS('Données - Équipes'!$C$5:$C$87,"Technicien 1",'Données - Équipes'!$F$5:$F$87,"MANQUE")+COUNTIFS('Données - Équipes'!$C$5:$C$87,"Technicien 2",'Données - Équipes'!$F$5:$F$87,"MANQUE") -> 3 | E44: =COUNTIF('Données - Équipes'!$C$91:$C$104,"Technicien") -> 3 | H44: Nord — Z1 | I44: =IF(COUNTIFS('Données - Équipes'!$G$5:$G$87,"Antenne Nord",'Données - Équipes'!$I$5:$I$87,1,'Données - Équipes'!$C$5:$C$87,"Ingénieur",'Données - Équipes'!$F$5:$F$87,"OK")>0,"OK","—") -> OK | J44: =IF(COUNTIFS('Données - Équipes'!$G$5:$G$87,"Antenne Nord",'Données - Équipes'!$I$5:$I$87,1,'Données - Équipes'!$C$5:$C$87,"Technicien 1",'Données - Équipes'!$F$5:$F$87,"OK")>0,"OK","—") -> OK | K44: =IF(COUNTIFS('Données - Équipes'!$G$5:$G$87,"Antenne Nord",'Données - Équipes'!$I$5:$I$87,1,'Données - Équipes'!$C$5:$C$87,"Technicien 2",'Données - Équipes'!$F$5:$F$87,"OK")>0,"OK","—") -> — | L44: =IF(COUNTIFS('Données - Équipes'!$G$5:$G$87,"Antenne Nord",'Données - Équipes'!$I$5:$I$87,1,'Données - Équipes'!$C$5:$C$87,"Chauffeur",'Données - Équipes'!$F$5:$F$87,"OK")>0,"OK","—") -> — | M44: =IF(COUNTIF(I44:L44,"OK")=4,"Complète",IF(COUNTIF(I44:L44,"OK")=0,"Critique","Partielle")) -> Partielle
A45: Chauffeur | B45: 16 | C45: =COUNTIFS('Données - Équipes'!$C$5:$C$87,"Chauffeur",'Données - Équipes'!$F$5:$F$87,"OK") -> 12 | D45: =COUNTIFS('Données - Équipes'!$C$5:$C$87,"Chauffeur",'Données - Équipes'!$F$5:$F$87,"MANQUE") -> 4 | E45: =COUNTIF('Données - Équipes'!$C$91:$C$104,"Chauffeur") -> 0 | H45: Nord — Z2 | I45: =IF(COUNTIFS('Données - Équipes'!$G$5:$G$87,"Antenne Nord",'Données - Équipes'!$I$5:$I$87,2,'Données - Équipes'!$C$5:$C$87,"Ingénieur",'Données - Équipes'!$F$5:$F$87,"OK")>0,"OK","—") -> — | J45: =IF(COUNTIFS('Données - Équipes'!$G$5:$G$87,"Antenne Nord",'Données - Équipes'!$I$5:$I$87,2,'Données - Équipes'!$C$5:$C$87,"Technicien 1",'Données - Équipes'!$F$5:$F$87,"OK")>0,"OK","—") -> OK | K45: =IF(COUNTIFS('Données - Équipes'!$G$5:$G$87,"Antenne Nord",'Données - Équipes'!$I$5:$I$87,2,'Données - Équipes'!$C$5:$C$87,"Technicien 2",'Données - Équipes'!$F$5:$F$87,"OK")>0,"OK","—") -> OK | L45: =IF(COUNTIFS('Données - Équipes'!$G$5:$G$87,"Antenne Nord",'Données - Équipes'!$I$5:$I$87,2,'Données - Équipes'!$C$5:$C$87,"Chauffeur",'Données - Équipes'!$F$5:$F$87,"OK")>0,"OK","—") -> OK | M45: =IF(COUNTIF(I45:L45,"OK")=4,"Complète",IF(COUNTIF(I45:L45,"OK")=0,"Critique","Partielle")) -> Partielle
A46: TOTAL | B46: =SUM(B43:B45) -> 64 | C46: =SUM(C43:C45) -> 47 | D46: =SUM(D43:D45) -> 17 | E46: =SUM(E43:E45) -> 6 | H46: Nord-Ouest — Z1 | I46: =IF(COUNTIFS('Données - Équipes'!$G$5:$G$87,"Antenne Nord-Ouest",'Données - Équipes'!$I$5:$I$87,1,'Données - Équipes'!$C$5:$C$87,"Ingénieur",'Données - Équipes'!$F$5:$F$87,"OK")>0,"OK","—") -> OK | J46: =IF(COUNTIFS('Données - Équipes'!$G$5:$G$87,"Antenne Nord-Ouest",'Données - Équipes'!$I$5:$I$87,1,'Données - Équipes'!$C$5:$C$87,"Technicien 1",'Données - Équipes'!$F$5:$F$87,"OK")>0,"OK","—") -> OK | K46: =IF(COUNTIFS('Données - Équipes'!$G$5:$G$87,"Antenne Nord-Ouest",'Données - Équipes'!$I$5:$I$87,1,'Données - Équipes'!$C$5:$C$87,"Technicien 2",'Données - Équipes'!$F$5:$F$87,"OK")>0,"OK","—") -> OK | L46: =IF(COUNTIFS('Données - Équipes'!$G$5:$G$87,"Antenne Nord-Ouest",'Données - Équipes'!$I$5:$I$87,1,'Données - Équipes'!$C$5:$C$87,"Chauffeur",'Données - Équipes'!$F$5:$F$87,"OK")>0,"OK","—") -> OK | M46: =IF(COUNTIF(I46:L46,"OK")=4,"Complète",IF(COUNTIF(I46:L46,"OK")=0,"Critique","Partielle")) -> Complète
H47: Nord-Ouest — Z2 | I47: =IF(COUNTIFS('Données - Équipes'!$G$5:$G$87,"Antenne Nord-Ouest",'Données - Équipes'!$I$5:$I$87,2,'Données - Équipes'!$C$5:$C$87,"Ingénieur",'Données - Équipes'!$F$5:$F$87,"OK")>0,"OK","—") -> — | J47: =IF(COUNTIFS('Données - Équipes'!$G$5:$G$87,"Antenne Nord-Ouest",'Données - Équipes'!$I$5:$I$87,2,'Données - Équipes'!$C$5:$C$87,"Technicien 1",'Données - Équipes'!$F$5:$F$87,"OK")>0,"OK","—") -> OK | K47: =IF(COUNTIFS('Données - Équipes'!$G$5:$G$87,"Antenne Nord-Ouest",'Données - Équipes'!$I$5:$I$87,2,'Données - Équipes'!$C$5:$C$87,"Technicien 2",'Données - Équipes'!$F$5:$F$87,"OK")>0,"OK","—") -> OK | L47: =IF(COUNTIFS('Données - Équipes'!$G$5:$G$87,"Antenne Nord-Ouest",'Données - Équipes'!$I$5:$I$87,2,'Données - Équipes'!$C$5:$C$87,"Chauffeur",'Données - Équipes'!$F$5:$F$87,"OK")>0,"OK","—") -> — | M47: =IF(COUNTIF(I47:L47,"OK")=4,"Complète",IF(COUNTIF(I47:L47,"OK")=0,"Critique","Partielle")) -> Partielle
H48: Nord-Ouest — Z3 | I48: =IF(COUNTIFS('Données - Équipes'!$G$5:$G$87,"Antenne Nord-Ouest",'Données - Équipes'!$I$5:$I$87,3,'Données - Équipes'!$C$5:$C$87,"Ingénieur",'Données - Équipes'!$F$5:$F$87,"OK")>0,"OK","—") -> — | J48: =IF(COUNTIFS('Données - Équipes'!$G$5:$G$87,"Antenne Nord-Ouest",'Données - Équipes'!$I$5:$I$87,3,'Données - Équipes'!$C$5:$C$87,"Technicien 1",'Données - Équipes'!$F$5:$F$87,"OK")>0,"OK","—") -> OK | K48: =IF(COUNTIFS('Données - Équipes'!$G$5:$G$87,"Antenne Nord-Ouest",'Données - Équipes'!$I$5:$I$87,3,'Données - Équipes'!$C$5:$C$87,"Technicien 2",'Données - Équipes'!$F$5:$F$87,"OK")>0,"OK","—") -> OK | L48: =IF(COUNTIFS('Données - Équipes'!$G$5:$G$87,"Antenne Nord-Ouest",'Données - Équipes'!$I$5:$I$87,3,'Données - Équipes'!$C$5:$C$87,"Chauffeur",'Données - Équipes'!$F$5:$F$87,"OK")>0,"OK","—") -> — | M48: =IF(COUNTIF(I48:L48,"OK")=4,"Complète",IF(COUNTIF(I48:L48,"OK")=0,"Critique","Partielle")) -> Partielle
H49: Adamaoua — Z1 | I49: =IF(COUNTIFS('Données - Équipes'!$G$5:$G$87,"Antenne Adamaoua",'Données - Équipes'!$I$5:$I$87,1,'Données - Équipes'!$C$5:$C$87,"Ingénieur",'Données - Équipes'!$F$5:$F$87,"OK")>0,"OK","—") -> OK | J49: =IF(COUNTIFS('Données - Équipes'!$G$5:$G$87,"Antenne Adamaoua",'Données - Équipes'!$I$5:$I$87,1,'Données - Équipes'!$C$5:$C$87,"Technicien 1",'Données - Équipes'!$F$5:$F$87,"OK")>0,"OK","—") -> OK | K49: =IF(COUNTIFS('Données - Équipes'!$G$5:$G$87,"Antenne Adamaoua",'Données - Équipes'!$I$5:$I$87,1,'Données - Équipes'!$C$5:$C$87,"Technicien 2",'Données - Équipes'!$F$5:$F$87,"OK")>0,"OK","—") -> — | L49: =IF(COUNTIFS('Données - Équipes'!$G$5:$G$87,"Antenne Adamaoua",'Données - Équipes'!$I$5:$I$87,1,'Données - Équipes'!$C$5:$C$87,"Chauffeur",'Données - Équipes'!$F$5:$F$87,"OK")>0,"OK","—") -> OK | M49: =IF(COUNTIF(I49:L49,"OK")=4,"Complète",IF(COUNTIF(I49:L49,"OK")=0,"Critique","Partielle")) -> Partielle
H50: Est — Z1 | I50: =IF(COUNTIFS('Données - Équipes'!$G$5:$G$87,"Antenne Est",'Données - Équipes'!$I$5:$I$87,1,'Données - Équipes'!$C$5:$C$87,"Ingénieur",'Données - Équipes'!$F$5:$F$87,"OK")>0,"OK","—") -> — | J50: =IF(COUNTIFS('Données - Équipes'!$G$5:$G$87,"Antenne Est",'Données - Équipes'!$I$5:$I$87,1,'Données - Équipes'!$C$5:$C$87,"Technicien 1",'Données - Équipes'!$F$5:$F$87,"OK")>0,"OK","—") -> OK | K50: =IF(COUNTIFS('Données - Équipes'!$G$5:$G$87,"Antenne Est",'Données - Équipes'!$I$5:$I$87,1,'Données - Équipes'!$C$5:$C$87,"Technicien 2",'Données - Équipes'!$F$5:$F$87,"OK")>0,"OK","—") -> OK | L50: =IF(COUNTIFS('Données - Équipes'!$G$5:$G$87,"Antenne Est",'Données - Équipes'!$I$5:$I$87,1,'Données - Équipes'!$C$5:$C$87,"Chauffeur",'Données - Équipes'!$F$5:$F$87,"OK")>0,"OK","—") -> OK | M50: =IF(COUNTIF(I50:L50,"OK")=4,"Complète",IF(COUNTIF(I50:L50,"OK")=0,"Critique","Partielle")) -> Partielle
...

Sheet Notes & méthodologie
A1: NOTES & MÉTHODOLOGIE — TABLEAU DE BORD AER (PARC SOLAIRE & RESSOURCES HUMAINES)
A3: A. Parc solaire — nettoyage des données et règles de rattachement (499 sites)
A5: 1. Régions harmonisées en français : « North » → Nord, « South-West » → Sud-Ouest, etc.
A6: 2. Départements harmonisés : variantes orthographiques unifiées (ex. « Mayo Rey I / II » → Mayo-Rey, « Kupe-Menenguba / KupeMuanenguba » → Kupé-Manenguba, « Mungo / Moungo » → Moungo).
A7: 3. Coordonnées : la Phase 2, fournie au format texte « N6.42 E13.38 », a été convertie en degrés décimaux numériques pour homogénéité avec les Phases 1 et 3.
A9: 4. Hypothèse non confirmée : vous avez indiqué « le département proche du Moungo du Sud-Ouest » sans le nommer. Kupé-Manenguba est le département du Sud-Ouest directement limitrophe du Moungo, mais Meme (Kumba) reste une alternative géographiquement plausible. À confirmer avant diffusion officielle — un changement ici déplace environ 15 à 20 sites entre Nkongsamba et Limbé.
A11: 5. Dimensionnement du personnel (feuille « Antennes — Détail solaire ») : chaque antenne reçoit un socle fixe de 2 postes (chef d'antenne + assistant administratif et financier), puis des ingénieurs techniques et des agents de développement communautaire au prorata du nombre de sites gérés (1 ingénieur / 25 sites, 1 agent communautaire / 30 sites — seuils modifiables en cellules N2:N3 de cette feuille, toute la feuille recalcule automatiquement). Cette règle est une proposition de départ, pas une norme validée par l'AER.
A13: B. Ressources humaines terrain — composition d'équipe et affectations (feuille « Données - Équipes »)
A15: 1. Composition d'équipe appliquée : 1 Ingénieur + 2 Techniciens + 1 Chauffeur par zone, sur les 16 zones (y compris Siège Yaoundé), sans exception.
A16: 2. Le profil de chaque agent est repris de son poste réel dans le fichier du personnel — pas du libellé de créneau (« Technicien 1 », etc.).
A17: 2 bis. Règles de correspondance poste → profil confirmées par vous : « Agent de maîtrise » et « Employé » (cas de MBELE Ben Thierry, Antenne Sud - Centre zone 2) comptent comme Technicien ; « Chef service » et « Architecte » comptent comme Ingénieur.
A18: 2 ter. Titres proches non couverts par votre règle, laissés en « Autre » par prudence (à confirmer si vous voulez les inclure) : « Chef d'Antenne » (NGUONAM Clement Tangjua, personnel non affecté) et les « Sous-Directeur » / « S/D » (postes de direction au Siège, personnel non affecté) — ce ne sont ni des « Chef service » ni des « Ingénieur » au sens strict du poste indiqué.
... A42: 4. Le plan d'action et le graphique de complétude sont calculés à partir des mêmes données sources que le reste du tableau de bord au moment de la génération de ce fichier ; si vous modifiez à nouveau les affectations dans « Données - Équipes », redemandez une régénération pour que ce plan reste synchronisé (contrairement aux formules Excel natives du reste du tableau de bord, qui recalculent automatiquement).

Sheet Antennes — Détail solaire
A1: ÉQUILIBRE DE LA CHARGE ET DIMENSIONNEMENT DU PERSONNEL PAR ANTENNE | N1: PARAMÈTRES
A2: Règle de dimensionnement (modifiable en cellules N2:N4) : 1 chef d'antenne + 1 assistant administratif par antenne (fixe) ; 1 ingénieur technique par tranche de 25 sites (minimum 1) ; 1 agent de développement communautaire par tranche de 30 sites (minimum 1). Toutes les cellules d'effectif sont des formules — modifier les seuils en N2:N4 recalcule automatiquement l'ensemble. | M2: Sites par ingénieur technique | N2: 25
M3: Sites par agent communautaire | N3: 30
A4: Antenne | B4: Type | C4: Rattachée à | D4: Régions / départements couverts | E4: Nb sites | F4: Puissance totale (kWc) | G4: Chef + admin | H4: Ingénieurs techniques | I4: Agents communautaires | J4: Effectif total | K4: Sites par agent | L4: % du total sites | M4: % de la puissance totale | N4: 2
A5: Antenne Bamenda | B5: Principale | D5: Nord-Ouest, Ouest | E5: =COUNTIF('Répartition par antenne'!$A$5:$A$503,$A5) -> 79 | F5: =SUMIF('Répartition par antenne'!$A$5:$A$503,$A5,'Répartition par antenne'!$E$5:$E$503) -> 5234.6 | G5: =$N$4 -> 2 | H5: =MAX(1,ROUNDUP(E5/$N$2,0)) -> 4 | I5: =MAX(1,ROUNDUP(E5/$N$3,0)) -> 3 | J5: =G5+H5+I5 -> 9 | K5: =IFERROR(E5/J5,0) -> 8.7777778 | L5: =E5/499 -> 0.15831663 | M5: =F5/32821.6 -> 0.15948644
A6: Antenne Limbé | B6: Principale | D6: Littoral (hors Moungo), Sud-Ouest (hors Kupé-Manenguba) | E6: =COUNTIF('Répartition par antenne'!$A$5:$A$503,$A6) -> 50 | F6: =SUMIF('Répartition par antenne'!$A$5:$A$503,$A6,'Répartition par antenne'!$E$5:$E$503) -> 2677.6 | G6: =$N$4 -> 2 | H6: =MAX(1,ROUNDUP(E6/$N$2,0)) -> 2 | I6: =MAX(1,ROUNDUP(E6/$N$3,0)) -> 2 | J6: =G6+H6+I6 -> 6 | K6: =IFERROR(E6/J6,0) -> 8.3333333 | L6: =E6/499 -> 0.1002004 | M6: =F6/32821.6 -> 0.081580423
A7: Antenne Nkongsamba | B7: Annexe | C7: Antenne Limbé | D7: Moungo, Kupé-Manenguba, Nyong-et-Kellé | E7: =COUNTIF('Répartition par antenne'!$A$5:$A$503,$A7) -> 29 | F7: =SUMIF('Répartition par antenne'!$A$5:$A$503,$A7,'Répartition par antenne'!$E$5:$E$503) -> 1433.6 | G7: =$N$4 -> 2 | H7: =MAX(1,ROUNDUP(E7/$N$2,0)) -> 2 | I7: =MAX(1,ROUNDUP(E7/$N$3,0)) -> 1 | J7: =G7+H7+I7 -> 5 | K7: =IFERROR(E7/J7,0) -> 5.8 | L7: =E7/499 -> 0.058116232 | M7: =F7/32821.6 -> 0.043678553
A8: Antenne Garoua | B8: Principale | D8: Nord | E8: =COUNTIF('Répartition par antenne'!$A$5:$A$503,$A8) -> 46 | F8: =SUMIF('Répartition par antenne'!$A$5:$A$503,$A8,'Répartition par antenne'!$E$5:$E$503) -> 4341 | G8: =$N$4 -> 2 | H8: =MAX(1,ROUNDUP(E8/$N$2,0)) -> 2 | I8: =MAX(1,ROUNDUP(E8/$N$3,0)) -> 2 | J8: =G8+H8+I8 -> 6 | K8: =IFERROR(E8/J8,0) -> 7.6666667 | L8: =E8/499 -> 0.092184369 | M8: =F8/32821.6 -> 0.13226046
A9: Antenne Maroua | B9: Annexe | C9: Antenne Garoua | D9: Extrême-Nord | E9: =COUNTIF('Répartition par antenne'!$A$5:$A$503,$A9) -> 34 | F9: =SUMIF('Répartition par antenne'!$A$5:$A$503,$A9,'Répartition par antenne'!$E$5:$E$503) -> 3110.4 | G9: =$N$4 -> 2 | H9: =MAX(1,ROUNDUP(E9/$N$2,0)) -> 2 | I9: =MAX(1,ROUNDUP(E9/$N$3,0)) -> 2 | J9: =G9+H9+I9 -> 6 | K9: =IFERROR(E9/J9,0) -> 5.6666667 | L9: =E9/499 -> 0.068136273 | M9: =F9/32821.6 -> 0.094766861
A10: Antenne Ngaoundéré | B10: Annexe | C10: Antenne Garoua | D10: Adamaoua | E10: =COUNTIF('Répartition par antenne'!$A$5:$A$503,$A10) -> 55 | F10: =SUMIF('Répartition par antenne'!$A$5:$A$503,$A10,'Répartition par antenne'!$E$5:$E$503) -> 4312.8 | G10: =$N$4 -> 2 | H10: =MAX(1,ROUNDUP(E10/$N$2,0)) -> 3 | I10: =MAX(1,ROUNDUP(E10/$N$3,0)) -> 2 | J10: =G10+H10+I10 -> 7 | K10: =IFERROR(E10/J10,0) -> 7.8571429 | L10: =E10/499 -> 0.11022044 | M10: =F10/32821.6 -> 0.13140127
A11: Siège Yaoundé | B11: Principale | D11: Centre — reste (Lekié, Mbam-et-Inoubou, Mbam-et-Kim, Mefou-et-Afamba, Mefou-et-Akono) | E11: =COUNTIF('Répartition par antenne'!$A$5:$A$503,$A11) -> 71 | F11: =SUMIF('Répartition par antenne'!$A$5:$A$503,$A11,'Répartition par antenne'!$E$5:$E$503) -> 4015.2 | G11: =$N$4 -> 2 | H11: =MAX(1,ROUNDUP(E11/$N$2,0)) -> 3 | I11: =MAX(1,ROUNDUP(E11/$N$3,0)) -> 3 | J11: =G11+H11+I11 -> 8 | K11: =IFERROR(E11/J11,0) -> 8.875 | L11: =E11/499 -> 0.14228457 | M11: =F11/32821.6 -> 0.12233407
A12: Antenne Bertoua | B12: Annexe | C12: Siège Yaoundé | D12: Est, Nyong-et-Mfoumou, Haute-Sanaga | E12: =COUNTIF('Répartition par antenne'!$A$5:$A$503,$A12) -> 68 | F12: =SUMIF('Répartition par antenne'!$A$5:$A$503,$A12,'Répartition par antenne'!$E$5:$E$503) -> 4498.2 | G12: =$N$4 -> 2 | H12: =MAX(1,ROUNDUP(E12/$N$2,0)) -> 3 | I12: =MAX(1,ROUNDUP(E12/$N$3,0)) -> 3 | J12: =G12+H12+I12 -> 8 | K12: =IFERROR(E12/J12,0) -> 8.5 | L12: =E12/499 -> 0.13627255 | M12: =F12/32821.6 -> 0.13704999
A13: Antenne Ebolowa | B13: Annexe | C13: Siège Yaoundé | D13: Sud, Nyong-et-So'o | E13: =COUNTIF('Répartition par antenne'!$A$5:$A$503,$A13) -> 67 | F13: =SUMIF('Répartition par antenne'!$A$5:$A$503,$A13,'Répartition par antenne'!$E$5:$E$503) -> 3198.2 | G13: =$N$4 -> 2 | H13: =MAX(1,ROUNDUP(E13/$N$2,0)) -> 3 | I13: =MAX(1,ROUNDUP(E13/$N$3,0)) -> 3 | J13: =G13+H13+I13 -> 8 | K13: =IFERROR(E13/J13,0) -> 8.375 | L13: =E13/499 -> 0.13426854 | M13: =F13/32821.6 -> 0.097441928
A14: TOTAL | E14: =SUM(E5:E13) -> 499 | F14: =SUM(F5:F13) -> 32821.6 | J14: =SUM(J5:J13) -> 63
A16: VUE PAR GROUPE (antenne principale + ses annexes)
A17: Groupe | B17: Nb sites (groupe) | C17: Puissance (kWc, groupe) | D17: Effectif (groupe) | E17: % du total sites
A18: Antenne Bamenda | B18: =SUM(E5:E5) -> 79 | C18: =SUM(F5:F5) -> 5234.6 | D18: =SUM(J5:J5) -> 9 | E18: =B18/499 -> 0.15831663
A19: Antenne Limbé | B19: =SUM(E6:E7) -> 79 | C19: =SUM(F6:F7) -> 4111.2 | D19: =SUM(J6:J7) -> 11 | E19: =B19/499 -> 0.15831663
A20: Antenne Garoua | B20: =SUM(E8:E10) -> 135 | C20: =SUM(F8:F10) -> 11764.2 | D20: =SUM(J8:J10) -> 19 | E20: =B20/499 -> 0.27054108
A21: Siège Yaoundé | B21: =SUM(E11:E13) -> 206 | C21: =SUM(F11:F13) -> 11711.6 | D21: =SUM(J11:J13) -> 24 | E21: =B21/499 -> 0.41282565
A22: TOTAL | B22: =B18+B19+B20+B21 -> 499 | C22: =C18+C19+C20+C21 -> 32821.6 | D22: =D18+D19+D20+D21 -> 63 | E22: =E19+E18+E20+E21 -> 1
A24: CONSTAT
A25: Structure hiérarchique à 4 antennes principales (Bamenda, Limbé, Garoua, Siège Yaoundé) et 5 annexes (Nkongsamba, Maroua, Ngaoundéré, Bertoua, Ebolowa). Les 499 sites sont intégralement couverts. L'effectif total se calcule automatiquement en colonne J — voir l'onglet Organigramme pour la représentation hiérarchique.
A27: Hypothèse à confirmer : le département de Kupé-Manenguba (Sud-Ouest) a été rattaché à Nkongsamba comme « département proche du Moungo » — Meme (Kumba) reste une alternative possible si votre intention était différente.

Sheet Répartition par antenne
A1: RÉPARTITION DES 499 SITES PAR ANTENNE PROPOSÉE
A2: Répartition transmise par l'AER (7 antennes + 1siege + 1 annexe)
A4: Antenne proposée | B4: Région | C4: Département | D4: Nom du site | E4: Puissance (kWc) | F4: Phase
A5: Antenne Bamenda | B5: Nord-Ouest | C5: Boyo | D5: Baiso | E5: 21.6 | F5: Phase 3
A6: Antenne Bamenda | B6: Nord-Ouest | C6: Boyo | D6: Bua Bua | E6: 100 | F6: Phase 1
A7: Antenne Bamenda | B7: Nord-Ouest | C7: Boyo | D7: Ekwijua | E7: 21.6 | F7: Phase 3
A8: Antenne Bamenda | B8: Nord-Ouest | C8: Boyo | D8: Fonfuka | E8: 80 | F8: Phase 1
A9: Antenne Bamenda | B9: Nord-Ouest | C9: Boyo | D9: Kimbi | E9: 81 | F9: Phase 3
A10: Antenne Bamenda | B10: Nord-Ouest | C10: Boyo | D10: Mejang | E10: 21.6 | F10: Phase 3
A11: Antenne Bamenda | B11: Nord-Ouest | C11: Boyo | D11: Nbueni | E11: 54 | F11: Phase 3
A12: Antenne Bamenda | B12: Nord-Ouest | C12: Bui | D12: Ndzevru | E12: 81 | F12: Phase 3
A13: Antenne Bamenda | B13: Nord-Ouest | C13: Bui | D13: Ngashie | E13: 140.4 | F13: Phase 3
A14: Antenne Bamenda | B14: Nord-Ouest | C14: Bui | D14: Ngendzen | E14: 81 | F14: Phase 3
A15: Antenne Bamenda | B15: Nord-Ouest | C15: Bui | D15: Sarkir | E15: 32.4 | F15: Phase 3
A16: Antenne Bamenda | B16: Nord-Ouest | C16: Donga-Mantung | D16: Akwenko | E16: 32.4 | F16: Phase 2
... A503: Siège Yaoundé | B503: Centre | C503: Mefou-et-Akono | D503: Songmimbias | E503: 54 | F503: Phase 3

Sheet Synthèse par région
A1: RÉPARTITION DES CENTRALES SOLAIRES PAR RÉGION, DÉPARTEMENT ET ARRONDISSEMENT
A2: Phases 1, 2 et 3 du programme national 499 sites au total.
A4: Région | B4: Département | C4: Arrondissement | D4: Nb sites | E4: Puissance totale (kWc) | F4: Puissance moyenne (kWc) | I4: antennes | J4: visites/mois =1
A5: Centre | D5: =COUNTIFS('Données sites'!$D$2:$D$500,$A5) -> 106 | E5: =SUMIFS('Données sites'!$G$2:$G$500,'Données sites'!$D$2:$D$500,$A5) -> 5363.4 | F5: =IFERROR(E5/D5,0) -> 50.598113 | I5: extreme-nord | J5: =D227/30 -> 1.1333333 | K5: 1
B6: Mbam-et-Kim | C6: Ngambe-Tikar | D6: =COUNTIFS('Données sites'!$D$2:$D$500,$A$5,'Données sites'!$E$2:$E$500,$B6,'Données sites'!$F$2:$F$500,$C6) -> 3 | E6: =SUMIFS('Données sites'!$G$2:$G$500,'Données sites'!$D$2:$D$500,$A$5,'Données sites'!$E$2:$E$500,$B6,'Données sites'!$F$2:$F$500,$C6) -> 280 | F6: =IFERROR(E6/D6,0) -> 93.333333 | I6: nord-ouest | J6: 2.6333333 | K6: 3
B7: Mbam-et-Kim | C7: Ngoro | D7: =COUNTIFS('Données sites'!$D$2:$D$500,$A$5,'Données sites'!$E$2:$E$500,$B7,'Données sites'!$F$2:$F$500,$C7) -> 3 | E7: =SUMIFS('Données sites'!$G$2:$G$500,'Données sites'!$D$2:$D$500,$A$5,'Données sites'!$E$2:$E$500,$B7,'Données sites'!$F$2:$F$500,$C7) -> 214 | F7: =IFERROR(E7/D7,0) -> 71.333333 | I7: nord | J7: =46/30 -> 1.5333333 | K7: 2
B8: Mbam-et-Kim | C8: Ntui | D8: =COUNTIFS('Données sites'!$D$2:$D$500,$A$5,'Données sites'!$E$2:$E$500,$B8,'Données sites'!$F$2:$F$500,$C8) -> 4 | E8: =SUMIFS('Données sites'!$G$2:$G$500,'Données sites'!$D$2:$D$500,$A$5,'Données sites'!$E$2:$E$500,$B8,'Données sites'!$F$2:$F$500,$C8) -> 330 | F8: =IFERROR(E8/D8,0) -> 82.5 | I8: adamaoua | J8: =55/30 -> 1.8333333 | K8: 2
B9: Mbam-et-Kim | C9: Yoko | D9: =COUNTIFS('Données sites'!$D$2:$D$500,$A$5,'Données sites'!$E$2:$E$500,$B9,'Données sites'!$F$2:$F$500,$C9) -> 10 | E9: =SUMIFS('Données sites'!$G$2:$G$500,'Données sites'!$D$2:$D$500,$A$5,'Données sites'!$E$2:$E$500,$B9,'Données sites'!$F$2:$F$500,$C9) -> 465 | F9: =IFERROR(E9/D9,0) -> 46.5 | I9: est | J9: =49/30 -> 1.6333333 | K9: 2
B10: Mefou-et-Akono | C10: Akono | D10: =COUNTIFS('Données sites'!$D$2:$D$500,$A$5,'Données sites'!$E$2:$E$500,$B10,'Données sites'!$F$2:$F$500,$C10) -> 5 | E10: =SUMIFS('Données sites'!$G$2:$G$500,'Données sites'!$D$2:$D$500,$A$5,'Données sites'!$E$2:$E$500,$B10,'Données sites'!$F$2:$F$500,$C10) -> 118.8 | F10: =IFERROR(E10/D10,0) -> 23.76 | I10: centre-sud | J10: =167/30 -> 5.5666667 | K10: 6
B11: Mefou-et-Akono | C11: Bikok | D11: =COUNTIFS('Données sites'!$D$2:$D$500,$A$5,'Données sites'!$E$2:$E$500,$B11,'Données sites'!$F$2:$F$500,$C11) -> 3 | E11: =SUMIFS('Données sites'!$G$2:$G$500,'Données sites'!$D$2:$D$500,$A$5,'Données sites'!$E$2:$E$500,$B11,'Données sites'!$F$2:$F$500,$C11) -> 140.4 | F11: =IFERROR(E11/D11,0) -> 46.8 | I11: sud-ouest | J11: =27/30 -> 0.9 | K11: 1
B12: Mefou-et-Akono | C12: Mbankomo | D12: =COUNTIFS('Données sites'!$D$2:$D$500,$A$5,'Données sites'!$E$2:$E$500,$B12,'Données sites'!$F$2:$F$500,$C12) -> 4 | E12: =SUMIFS('Données sites'!$G$2:$G$500,'Données sites'!$D$2:$D$500,$A$5,'Données sites'!$E$2:$E$500,$B12,'Données sites'!$F$2:$F$500,$C12) -> 97.2 | F12: =IFERROR(E12/D12,0) -> 24.3 | I12: annexe-sud ouest | J12: =42/30 -> 1.4 | K12: 1
B13: Mefou-et-Akono | C13: Ngoumou | D13: =COUNTIFS('Données sites'!$D$2:$D$500,$A$5,'Données sites'!$E$2:$E$500,$B13,'Données sites'!$F$2:$F$500,$C13) -> 5 | E13: =SUMIFS('Données sites'!$G$2:$G$500,'Données sites'!$D$2:$D$500,$A$5,'Données sites'!$E$2:$E$500,$B13,'Données sites'!$F$2:$F$500,$C13) -> 281.2 | F13: =IFERROR(E13/D13,0) -> 56.24
B14: Haute-Sanaga | C14: Afanloum | D14: =COUNTIFS('Données sites'!$D$2:$D$500,$A$5,'Données sites'!$E$2:$E$500,$B14,'Données sites'!$F$2:$F$500,$C14) -> 1 | E14: =SUMIFS('Données sites'!$G$2:$G$500,'Données sites'!$D$2:$D$500,$A$5,'Données sites'!$E$2:$E$500,$B14,'Données sites'!$F$2:$F$500,$C14) -> 81 | F14: =IFERROR(E14/D14,0) -> 81
B15: Haute-Sanaga | C15: Lembe Yezoum | D15: =COUNTIFS('Données sites'!$D$2:$D$500,$A$5,'Données sites'!$E$2:$E$500,$B15,'Données sites'!$F$2:$F$500,$C15) -> 5 | E15: =SUMIFS('Données sites'!$G$2:$G$500,'Données sites'!$D$2:$D$500,$A$5,'Données sites'!$E$2:$E$500,$B15,'Données sites'!$F$2:$F$500,$C15) -> 194 | F15: =IFERROR(E15/D15,0) -> 38.8
B16: Haute-Sanaga | C16: Lembe-Yezoum | D16: =COUNTIFS('Données sites'!$D$2:$D$500,$A$5,'Données sites'!$E$2:$E$500,$B16,'Données sites'!$F$2:$F$500,$C16) -> 2 | E16: =SUMIFS('Données sites'!$G$2:$G$500,'Données sites'!$D$2:$D$500,$A$5,'Données sites'!$E$2:$E$500,$B16,'Données sites'!$F$2:$F$500,$C16) -> 75.6 | F16: =IFERROR(E16/D16,0) -> 37.8
B17: Haute-Sanaga | C17: Minta | D17: =COUNTIFS('Données sites'!$D$2:$D$500,$A$5,'Données sites'!$E$2:$E$500,$B17,'Données sites'!$F$2:$F$500,$C17) -> 1 | E17: =SUMIFS('Données sites'!$G$2:$G$500,'Données sites'!$D$2:$D$500,$A$5,'Données sites'!$E$2:$E$500,$B17,'Données sites'!$F$2:$F$500,$C17) -> 32.4 | F17: =IFERROR(E17/D17,0) -> 32.4
B18: Haute-Sanaga | C18: Nanga Eboko | D18: =COUNTIFS('Données sites'!$D$2:$D$500,$A$5,'Données sites'!$E$2:$E$500,$B18,'Données sites'!$F$2:$F$500,$C18) -> 3 | E18: =SUMIFS('Données sites'!$G$2:$G$500,'Données sites'!$D$2:$D$500,$A$5,'Données sites'!$E$2:$E$500,$B18,'Données sites'!$F$2:$F$500,$C18) -> 97.2 | F18: =IFERROR(E18/D18,0) -> 32.4
B19: Haute-Sanaga | C19: Nanga-Eboko | D19: =COUNTIFS('Données sites'!$D$2:$D$500,$A$5,'Données sites'!$E$2:$E$500,$B19,'Données sites'!$F$2:$F$500,$C19) -> 2 | E19: =SUMIFS('Données sites'!$G$2:$G$500,'Données sites'!$D$2:$D$500,$A$5,'Données sites'!$E$2:$E$500,$B19,'Données sites'!$F$2:$F$500,$C19) -> 64.8 | F19: =IFERROR(E19/D19,0) -> 32.4
B20: Haute-Sanaga | C20: Nsem | D20: =COUNTIFS('Données sites'!$D$2:$D$500,$A$5,'Données sites'!$E$2:$E$500,$B20,'Données sites'!$F$2:$F$500,$C20) -> 2 | E20: =SUMIFS('Données sites'!$G$2:$G$500,'Données sites'!$D$2:$D$500,$A$5,'Données sites'!$E$2:$E$500,$B20,'Données sites'!$F$2:$F$500,$C20) -> 101.6 | F20: =IFERROR(E20/D20,0) -> 50.8
B21: Mbam-et-Inoubou | C21: Bokito | D21: =COUNTIFS('Données sites'!$D$2:$D$500,$A$5,'Données sites'!$E$2:$E$500,$B21,'Données sites'!$F$2:$F$500,$C21) -> 2 | E21: =SUMIFS('Données sites'!$G$2:$G$500,'Données sites'!$D$2:$D$500,$A$5,'Données sites'!$E$2:$E$500,$B21,'Données sites'!$F$2:$F$500,$C21) -> 47.4 | F21: =IFERROR(E21/D21,0) -> 23.7
B22: Mbam-et-Inoubou | C22: Deuk | D22: =COUNTIFS('Données sites'!$D$2:$D$500,$A$5,'Données sites'!$E$2:$E$500,$B22,'Données sites'!$F$2:$F$500,$C22) -> 3 | E22: =SUMIFS('Données sites'!$G$2:$G$500,'Données sites'!$D$2:$D$500,$A$5,'Données sites'!$E$2:$E$500,$B22,'Données sites'!$F$2:$F$500,$C22) -> 189 | F22: =IFERROR(E22/D22,0) -> 63
B23: Mbam-et-Inoubou | C23: KiKi | D23: =COUNTIFS('Données sites'!$D$2:$D$500,$A$5,'Données sites'!$E$2:$E$500,$B23,'Données sites'!$F$2:$F$500,$C23) -> 1 | E23: =SUMIFS('Données sites'!$G$2:$G$500,'Données sites'!$D$2:$D$500,$A$5,'Données sites'!$E$2:$E$500,$B23,'Données sites'!$F$2:$F$500,$C23) -> 81 | F23: =IFERROR(E23/D23,0) -> 81
B24: Mbam-et-Inoubou | C24: Kon-Yambetta | D24: =COUNTIFS('Données sites'!$D$2:$D$500,$A$5,'Données sites'!$E$2:$E$500,$B24,'Données sites'!$F$2:$F$500,$C24) -> 3 | E24: =SUMIFS('Données sites'!$G$2:$G$500,'Données sites'!$D$2:$D$500,$A$5,'Données sites'!$E$2:$E$500,$B24,'Données sites'!$F$2:$F$500,$C24) -> 240 | F24: =IFERROR(E24/D24,0) -> 80
... B51: Nyong-et-Mfoumou | C51: Nyakokombo | D51: =COUNTIFS('Données sites'!$D$2:$D$500,$A$5,'Données sites'!$E$2:$E$500,$B51,'Données sites'!$F$2:$F$500,$C51) -> 1 | E51: =SUMIFS('Données sites'!$G$2:$G$500,'Données sites'!$D$2:$D$500,$A$5,'Données sites'!$E$2:$E$500,$B51,'Données sites'!$F$2:$F$500,$C51) -> 97.2 | F51: =IFERROR(E51/D51,0) -> 97.2
A52: Sud | D52: =COUNTIFS('Données sites'!$D$2:$D$500,$A52) -> 61 | E52: =SUMIFS('Données sites'!$G$2:$G$500,'Données sites'!$D$2:$D$500,$A52) -> 2960.6 | F52: =IFERROR(E52/D52,0) -> 48.534426
B53: Dja-et-Lobo | C53: Bengbis | D53: =COUNTIFS('Données sites'!$D$2:$D$500,$A$52,'Données sites'!$E$2:$E$500,$B53,'Données sites'!$F$2:$F$500,$C53) -> 3 | E53: =SUMIFS('Données sites'!$G$2:$G$500,'Données sites'!$D$2:$D$500,$A$52,'Données sites'!$E$2:$E$500,$B53,'Données sites'!$F$2:$F$500,$C53) -> 156.6 | F53: =IFERROR(E53/D53,0) -> 52.2
B54: Dja-et-Lobo | C54: Djoum | D54: =COUNTIFS('Données sites'!$D$2:$D$500,$A$52,'Données sites'!$E$2:$E$500,$B54,'Données sites'!$F$2:$F$500,$C54) -> 2 | E54: =SUMIFS('Données sites'!$G$2:$G$500,'Données sites'!$D$2:$D$500,$A$52,'Données sites'!$E$2:$E$500,$B54,'Données sites'!$F$2:$F$500,$C54) -> 86.4 | F54: =IFERROR(E54/D54,0) -> 43.2
B55: Dja-et-Lobo | C55: Haut Nyong | D55: =COUNTIFS('Données sites'!$D$2:$D$500,$A$52,'Données sites'!$E$2:$E$500,$B55,'Données sites'!$F$2:$F$500,$C55) -> 1 | E55: =SUMIFS('Données sites'!$G$2:$G$500,'Données sites'!$D$2:$D$500,$A$52,'Données sites'!$E$2:$E$500,$B55,'Données sites'!$F$2:$F$500,$C55) -> 80 | F55: =IFERROR(E55/D55,0) -> 80
B56: Dja-et-Lobo | C56: MeYomessi | D56: =COUNTIFS('Données sites'!$D$2:$D$500,$A$52,'Données sites'!$E$2:$E$500,$B56,'Données sites'!$F$2:$F$500,$C56) -> 1 | E56: =SUMIFS('Données sites'!$G$2:$G$500,'Données sites'!$D$2:$D$500,$A$52,'Données sites'!$E$2:$E$500,$B56,'Données sites'!$F$2:$F$500,$C56) -> 80 | F56: =IFERROR(E56/D56,0) -> 80
B57: Dja-et-Lobo | C57: Meyomessala | D57: =COUNTIFS('Données sites'!$D$2:$D$500,$A$52,'Données sites'!$E$2:$E$500,$B57,'Données sites'!$F$2:$F$500,$C57) -> 2 | E57: =SUMIFS('Données sites'!$G$2:$G$500,'Données sites'!$D$2:$D$500,$A$52,'Données sites'!$E$2:$E$500,$B57,'Données sites'!$F$2:$F$500,$C57) -> 62.4 | F57: =IFERROR(E57/D57,0) -> 31.2
B58: Dja-et-Lobo | C58: Mintom | D58: =COUNTIFS('Données sites'!$D$2:$D$500,$A$52,'Données sites'!$E$2:$E$500,$B58,'Données sites'!$F$2:$F$500,$C58) -> 6 | E58: =SUMIFS('Données sites'!$G$2:$G$500,'Données sites'!$D$2:$D$500,$A$52,'Données sites'!$E$2:$E$500,$B58,'Données sites'!$F$2:$F$500,$C58) -> 268 | F58: =IFERROR(E58/D58,0) -> 44.666667
B59: Dja-et-Lobo | C59: Oveng | D59: =COUNTIFS('Données sites'!$D$2:$D$500,$A$52,'Données sites'!$E$2:$E$500,$B59,'Données sites'!$F$2:$F$500,$C59) -> 4 | E59: =SUMIFS('Données sites'!$G$2:$G$500,'Données sites'!$D$2:$D$500,$A$52,'Données sites'!$E$2:$E$500,$B59,'Données sites'!$F$2:$F$500,$C59) -> 186.4 | F59: =IFERROR(E59/D59,0) -> 46.6
B60: Dja-et-Lobo | C60: Sangmelima | D60: =COUNTIFS('Données sites'!$D$2:$D$500,$A$52,'Données sites'!$E$2:$E$500,$B60,'Données sites'!$F$2:$F$500,$C60) -> 1 | E60: =SUMIFS('Données sites'!$G$2:$G$500,'Données sites'!$D$2:$D$500,$A$52,'Données sites'!$E$2:$E$500,$B60,'Données sites'!$F$2:$F$500,$C60) -> 50 | F60: =IFERROR(E60/D60,0) -> 50
B61: Dja-et-Lobo | C61: Zoétélé | D61: =COUNTIFS('Données sites'!$D$2:$D$500,$A$52,'Données sites'!$E$2:$E$500,$B61,'Données sites'!$F$2:$F$500,$C61) -> 2 | E61: =SUMIFS('Données sites'!$G$2:$G$500,'Données sites'!$D$2:$D$500,$A$52,'Données sites'!$E$2:$E$500,$B61,'Données sites'!$F$2:$F$500,$C61) -> 80 | F61: =IFERROR(E61/D61,0) -> 40
B62: Mvila | C62: Biwong Bane | D62: =COUNTIFS('Données sites'!$D$2:$D$500,$A$52,'Données sites'!$E$2:$E$500,$B62,'Données sites'!$F$2:$F$500,$C62) -> 1 | E62: =SUMIFS('Données sites'!$G$2:$G$500,'Données sites'!$D$2:$D$500,$A$52,'Données sites'!$E$2:$E$500,$B62,'Données sites'!$F$2:$F$500,$C62) -> 30 | F62: =IFERROR(E62/D62,0) -> 30
B63: Mvila | C63: Biwong Bulu | D63: =COUNTIFS('Données sites'!$D$2:$D$500,$A$52,'Données sites'!$E$2:$E$500,$B63,'Données sites'!$F$2:$F$500,$C63) -> 2 | E63: =SUMIFS('Données sites'!$G$2:$G$500,'Données sites'!$D$2:$D$500,$A$52,'Données sites'!$E$2:$E$500,$B63,'Données sites'!$F$2:$F$500,$C63) -> 160 | F63: =IFERROR(E63/D63,0) -> 80
B64: Mvila | C64: Biwong-Bane | D64: =COUNTIFS('Données sites'!$D$2:$D$500,$A$52,'Données sites'!$E$2:$E$500,$B64,'Données sites'!$F$2:$F$500,$C64) -> 1 | E64: =SUMIFS('Données sites'!$G$2:$G$500,'Données sites'!$D$2:$D$500,$A$52,'Données sites'!$E$2:$E$500,$B64,'Données sites'!$F$2:$F$500,$C64) -> 21.6 | F64: =IFERROR(E64/D64,0) -> 21.6
... B83: Vallée-du-Ntem | C83: Olamze | D83: =COUNTIFS('Données sites'!$D$2:$D$500,$A$52,'Données sites'!$E$2:$E$500,$B83,'Données sites'!$F$2:$F$500,$C83) -> 1 | E83: =SUMIFS('Données sites'!$G$2:$G$500,'Données sites'!$D$2:$D$500,$A$52,'Données sites'!$E$2:$E$500,$B83,'Données sites'!$F$2:$F$500,$C83) -> 54 | F83: =IFERROR(E83/D83,0) -> 54
A84: Adamaoua | D84: =COUNTIFS('Données sites'!$D$2:$D$500,$A84) -> 55 | E84: =SUMIFS('Données sites'!$G$2:$G$500,'Données sites'!$D$2:$D$500,$A84) -> 4312.8 | F84: =IFERROR(E84/D84,0) -> 78.414545
B85: Mayo-Banyo | C85: Bamkim | D85: =COUNTIFS('Données sites'!$D$2:$D$500,$A$84,'Données sites'!$E$2:$E$500,$B85,'Données sites'!$F$2:$F$500,$C85) -> 1 | E85: =SUMIFS('Données sites'!$G$2:$G$500,'Données sites'!$D$2:$D$500,$A$84,'Données sites'!$E$2:$E$500,$B85,'Données sites'!$F$2:$F$500,$C85) -> 100 | F85: =IFERROR(E85/D85,0) -> 100
...

Sheet Données sites
A1: Phase | B1: N° | C1: Nom du site | D1: Région | E1: Département | F1: Arrondissement | G1: Puissance (kWc) | H1: Latitude (N) | I1: Longitude (E) | J1: Antenne proposée
A2: Phase 2 | B2: 3 | C2: Danfili | D2: Adamaoua | E2: Djerem | F2: Ngaoundal | G2: 183.6 | H2: 6.6004 | I2: 13.00881 | J2: Antenne Ngaoundéré
A3: Phase 2 | B3: 2 | C3: Daber | D3: Adamaoua | E3: Djerem | F3: Tibati | G3: 81 | H3: 6.61549 | I3: 12.09635 | J3: Antenne Ngaoundéré
A4: Phase 2 | B4: 7 | C4: Mbamti-Katarko | D4: Adamaoua | E4: Djerem | F4: Tibati | G4: 32.4 | H4: 6.68185 | I4: 12.02323 | J4: Antenne Ngaoundéré
A5: Phase 1 | B5: 1 | C5: Mbella Assom | D5: Adamaoua | E5: Djerem | F5: Tibati | G5: 30 | H5: 6.6092167 | I5: 12.985233 | J5: Antenne Ngaoundéré
A6: Phase 3 | B6: 2 | C6: Minam | D6: Adamaoua | E6: Djerem | F6: Tibati | G6: 81 | H6: 6.971452 | I6: 12.872891 | J6: Antenne Ngaoundéré
A7: Phase 2 | B7: 9 | C7: Tongo | D7: Adamaoua | E7: Djerem | F7: Tibati | G7: 81 | H7: 6.59072 | I7: 12.249 | J7: Antenne Ngaoundéré
A8: Phase 3 | B8: 5 | C8: Lompta | D8: Adamaoua | E8: Faro-et-Déo | F8: Galim Tignere | G8: 54 | H8: 7.052538 | I8: 12.523423 | J8: Antenne Ngaoundéré
A9: Phase 2 | B9: 5 | C9: Doualayel | D9: Adamaoua | E9: Faro-et-Déo | F9: Galim-Tignere | G9: 183.6 | H9: 7.01107 | I9: 12.65258 | J9: Antenne Ngaoundéré
A10: Phase 1 | B10: 8 | C10: Galim-Tignere | D10: Adamaoua | E10: Faro-et-Déo | F10: Galim-Tignère | G10: 80 | H10: 7.1074 | I10: 12.4704 | J10: Antenne Ngaoundéré
A11: Phase 3 | B11: 12 | C11: Gadamayo | D11: Adamaoua | E11: Faro-et-Déo | F11: Kontcha | G11: 32.4 | H11: 7.955817 | I11: 12.252276 | J11: Antenne Ngaoundéré
A12: Phase 1 | B12: 18 | C12: Alme | D12: Adamaoua | E12: Faro-et-Déo | F12: Mayo-Baléo | G12: 80 | H12: 7.8227 | I12: 12.4893 | J12: Antenne Ngaoundéré
A13: Phase 1 | B13: 7 | C13: Mayo-Baleo | D13: Adamaoua | E13: Faro-et-Déo | F13: Mayo-Baléo | G13: 80 | H13: 7.6688167 | I13: 12.3261 | J13: Antenne Ngaoundéré
... A500: Phase 3 | B500: 132 | C500: Ikoti | D500: Sud-Ouest | E500: Ndian | F500: Toko | G500: 32.4 | H500: 5.0478 | I500: 9.111189 | J500: Antenne Limbé

Sheet Organigramme
B1: ORGANIGRAMME DU RÉSEAU D'ANTENNES AER
B2: 4 antennes principales, 5 annexes rattachées. Les effectifs affichés reprennent l'onglet Antennes — Détail solaire.
N4: AGENCE D'ÉLECTRIFICATION RURALE
N6: Siège — Yaoundé
B8: ANTENNE BAMENDA | I8: ANTENNE LIMBÉ | P8: ANTENNE GAROUA | AA8: SIÈGE YAOUNDÉ
B10: Nord-Ouest, Ouest | I10: Littoral, Sud-Ouest | P10: Nord | AA10: Centre
I12: Annexe NKONGSAMBA | N12: Annexe MAROUA | S12: Annexe NGAOUNDÉRÉ | W12: Annexe BERTOUA | AB12: Annexe EBOLOWA
I14: Moungo, Kupé-Manenguba | N14: Extrême-Nord | S14: Adamaoua | W14: Est, Nyong-Mfoumou, Ht-Sanaga | AB14: Sud + Nyong-et-So'o
B17: LÉGENDE
C18: Siège AER
C19: Antenne principale
C20: Annexe (rattachée à une antenne principale)
B22: Chaque annexe est administrativement rattachée à son antenne principale plutôt que de fonctionner de façon autonome : Nkongsamba dépend de Limbé ; Maroua et Ngaoundéré dépendent de Garoua ; Bertoua et Ebolowa dépendent du Siège Yaoundé. Voir l'onglet Antennes — Détail solaire pour le détail chiffré par structure et la vue consolidée par groupe.

Sheet Données - Équipes
A1: EFFECTIFS AER — ÉQUIPES TERRAIN (1 Ingénieur + 2 Techniciens + 1 Chauffeur par équipe)
A2: Personnel additionnel = agent présent sur la zone mais dont le profil ne correspond à aucun des 3 postes-type de l'équipe.
A4: Antenne | B4: Zone | C4: Rôle | D4: Agent affecté | E4: Poste (fichier RH) | F4: Statut | G4: Antenne (rempli) | H4: Région (hypothèse) | I4: Zone (rempli)
A5: Antenne Extreme-Nord | B5: 1 | C5: Ingénieur | D5: — MANQUANT — | F5: MANQUE | G5: Antenne Extreme-Nord | H5: Extrême-Nord | I5: 1
C6: Technicien 1 | D6: YANGAI Bekolo Emmanuel Parfait | E6: Agent de maitrise | F6: OK | G6: Antenne Extreme-Nord | H6: Extrême-Nord | I6: 1
C7: Technicien 2 | D7: ADAMOU Abba Badamassi | E7: Agent de maitrise | F7: OK | G7: Antenne Extreme-Nord | H7: Extrême-Nord | I7: 1
C8: Chauffeur | D8: IBRAHIMA | E8: Chauffeur | F8: OK | G8: Antenne Extreme-Nord | H8: Extrême-Nord | I8: 1
G9: Antenne Extreme-Nord | H9: Extrême-Nord | I9: 1
A10: Antenne Nord | B10: 1 | C10: Ingénieur | D10: DJAWOE Samuel | E10: Ingenieur / CS | F10: OK | G10: Antenne Nord | H10: Nord | I10: 1
C11: Technicien 1 | D11: HAMADOU Mousa | E11: Technicien | F11: OK | G11: Antenne Nord | H11: Nord | I11: 1
C12: Technicien 2 | D12: — MANQUANT — | F12: MANQUE | G12: Antenne Nord | H12: Nord | I12: 1
C13: Chauffeur | D13: — MANQUANT — | F13: MANQUE | G13: Antenne Nord | H13: Nord | I13: 1
G14: Antenne Nord | H14: Nord | I14: 1
A15: Antenne Nord | B15: 2 | C15: Ingénieur | D15: — MANQUANT — | F15: MANQUE | G15: Antenne Nord | H15: Nord | I15: 2
C16: Technicien 1 | D16: ABDOULAYE AWAH Salam | E16: Technicien | F16: OK | G16: Antenne Nord | H16: Nord | I16: 2
C17: Technicien 2 | D17: TIAM TIAGHOUE Valery | E17: Technicien | F17: OK | G17: Antenne Nord | H17: Nord | I17: 2
C18: Chauffeur | D18: CHAMSSOUDINNI Boukar | E18: Chauffeur | F18: OK | G18: Antenne Nord | H18: Nord | I18: 2
G19: Antenne Nord | H19: Nord | I19: 2
A20: Antenne Nord-Ouest | B20: 1 | C20: Ingénieur | D20: TAGNE Duclair | E20: Chef service antenne du Nord | F20: OK | G20: Antenne Nord-Ouest | H20: Nord-Ouest | I20: 1
C21: Technicien 1 | D21: DICOUM Vincent | E21: Technicien | F21: OK | G21: Antenne Nord-Ouest | H21: Nord-Ouest | I21: 1
C22: Technicien 2 | D22: WABILA Patrick | E22: Technicien | F22: OK | G22: Antenne Nord-Ouest | H22: Nord-Ouest | I22: 1
C23: Chauffeur | D23: CHEKO JOHN NFOMBE | E23: Chauffeur | F23: OK | G23: Antenne Nord-Ouest | H23: Nord-Ouest | I23: 1
G24: Antenne Nord-Ouest | H24: Nord-Ouest | I24: 1
A25: Antenne Nord-Ouest | B25: 2 | C25: Ingénieur | D25: — MANQUANT — | F25: MANQUE | G25: Antenne Nord-Ouest | H25: Nord-Ouest | I25: 2
C26: Technicien 1 | D26: NGANGNDI Nelson Ful | E26: Technicien | F26: OK | G26: Antenne Nord-Ouest | H26: Nord-Ouest | I26: 2
C27: Technicien 2 | D27: NGANDI PAUL AYEAH | E27: Agent de maitrise | F27: OK | G27: Antenne Nord-Ouest | H27: Nord-Ouest | I27: 2
C28: Chauffeur | D28: — MANQUANT — | F28: MANQUE | G28: Antenne Nord-Ouest | H28: Nord-Ouest | I28: 2
C29: (additionnel) | D29: HANSON Anyere | E29: Agent de maitrise | F29: PERSONNEL ADDITIONNEL (hors profil-type) | G29: Antenne Nord-Ouest | H29: Nord-Ouest | I29: 2
G30: Antenne Nord-Ouest | H30: Nord-Ouest | I30: 2
A31: Antenne Nord-Ouest | B31: 3 | C31: Ingénieur | D31: — MANQUANT — | F31: MANQUE | G31: Antenne Nord-Ouest | H31: Nord-Ouest | I31: 3
C32: Technicien 1 | D32: NDIKEBAH DIVINE MAWOH | E32: Agent de maitrise | F32: OK | G32: Antenne Nord-Ouest | H32: Nord-Ouest | I32: 3
C33: Technicien 2 | D33: NOUMBISSI TEKEM HERMAN | E33: Technicien | F33: OK | G33: Antenne Nord-Ouest | H33: Nord-Ouest | I33: 3
C34: Chauffeur | D34: — MANQUANT — | F34: MANQUE | G34: Antenne Nord-Ouest | H34: Nord-Ouest | I34: 3
G35: Antenne Nord-Ouest | H35: Nord-Ouest | I35: 3
A36: Antenne Adamaoua | B36: 1 | C36: Ingénieur | D36: ABOUBAKAR Siddik | E36: Ingenieur | F36: OK | G36: Antenne Adamaoua | H36: Adamaoua | I36: 1
C37: Technicien 1 | D37: ABBA Ilyassa | E37: Technicien | F37: OK | G37: Antenne Adamaoua | H37: Adamaoua | I37: 1
C38: Technicien 2 | D38: — MANQUANT — | F38: MANQUE | G38: Antenne Adamaoua | H38: Adamaoua | I38: 1
C39: Chauffeur | D39: BOUBAKARY Abba Souleymanou | E39: Chauffeur | F39: OK | G39: Antenne Adamaoua | H39: Adamaoua | I39: 1
G40: Antenne Adamaoua | H40: Adamaoua | I40: 1
A41: Antenne Est | B41: 1 | C41: Ingénieur | D41: — MANQUANT — | F41: MANQUE | G41: Antenne Est | H41: Est | I41: 1
...
